Workbook

Sheet Dashboard
A1: COLLEGE PLACEMENT ANALYTICS
A4: Student Placement & Recruitment Insights
A6: TOTAL STUDENTS | D6: PLACED STUDENTS | G6: PLACEMENT RATE | J6: AVERAGE PACKAGE | M6: HIGHEST PACKAGE | P6: TOTAL OFFERS
A7: =Summary!B3 -> 3500 | D7: =Summary!B4 -> 2780 | G7: =Summary!B6 -> 0.79428571 | J7: =Summary!B7 -> 9.1315899 | M7: =Summary!B8 -> 23.34 | P7: =Summary!B10 -> 4181
A11: PLACEMENT OVERVIEW
A28: PACKAGE & RECRUITMENT INSIGHTS
A45: INTERACTIVE FILTER PANEL (choose a value, or "All" — the KPIs below update live)
B46: Department: | H46: Academic Year: | N46: Gender:
B47: All | H47: All | N47: All
A49: Filtered Students | F49: Filtered Placed | K49: Filtered Placement Rate | O49: Filtered Avg Package (LPA)
A50: =SUMPRODUCT((((Raw_Data!$C$2:$C$3501=$B$47)+($B$47="All"))>0)*(((Raw_Data!$B$2:$B$3501=$H$47)+($H$47="All"))>0)*(((Raw_Data!$D$2:$D$3501=$N$47)+($N$47="All"))>0)) -> 3500 | F50: =SUMPRODUCT((((Raw_Data!$C$2:$C$3501=$B$47)+($B$47="All"))>0)*(((Raw_Data!$B$2:$B$3501=$H$47)+($H$47="All"))>0)*(((Raw_Data!$D$2:$D$3501=$N$47)+($N$47="All"))>0)*(Raw_Data!$O$2:$O$3501="Placed")) -> 2780 | K50: =IFERROR(F50/A50,0) -> 0.79428571 | O50: =IFERROR(SUMPRODUCT((((Raw_Data!$C$2:$C$3501=$B$47)+($B$47="All"))>0)*(((Raw_Data!$B$2:$B$3501=$H$47)+($H$47="All"))>0)*(((Raw_Data!$D$2:$D$3501=$N$47)+($N$47="All"))>0)*(Raw_Data!$O$2:$O$3501="Placed")*Raw_Data!$S$2:$S$3501)/F50,0) -> 9.1315899
A53: KEY INSIGHTS
A54: Department with highest placement rate: | H54: =INDEX(Pivot_Tables!$A$25:$A$31,MATCH(MAX(Pivot_Tables!$E$25:$E$31),Pivot_Tables!$E$25:$E$31,0))&" ("&TEXT(MAX(Pivot_Tables!$E$25:$E$31),"0.0%")&")" -> MECH (83.3%)
A55: Company hiring the most students: | H55: =INDEX(Pivot_Tables!$A$65:$A$74,MATCH(MAX(Pivot_Tables!$B$65:$B$74),Pivot_Tables!$B$65:$B$74,0))&" ("&MAX(Pivot_Tables!$B$65:$B$74)&" students)" -> Accenture (298 students)
A56: Company with the highest average package: | H56: =INDEX(Pivot_Tables!$A$105:$A$114,MATCH(MAX(Pivot_Tables!$B$105:$B$114),Pivot_Tables!$B$105:$B$114,0))&" ("&TEXT(MAX(Pivot_Tables!$B$105:$B$114),"0.00")&" LPA)" -> Microsoft (19.56 LPA)
A57: Department with the highest average package: | H57: =INDEX(Pivot_Tables!$A$85:$A$91,MATCH(MAX(Pivot_Tables!$B$85:$B$91),Pivot_Tables!$B$85:$B$91,0))&" ("&TEXT(MAX(Pivot_Tables!$B$85:$B$91),"0.00")&" LPA)" -> MECH (9.38 LPA)
A58: Academic year with the highest placement rate: | H58: =INDEX(Pivot_Tables!$A$45:$A$49,MATCH(MAX(Pivot_Tables!$C$45:$C$49),Pivot_Tables!$C$45:$C$49,0))&" ("&TEXT(MAX(Pivot_Tables!$C$45:$C$49),"0.0%")&")" -> 2023-24 (81.1%)
A59: Placement rate – students WITH internships vs WITHOUT: | H59: =TEXT(COUNTIFS(Raw_Data!$H$2:$H$3501,">0",Raw_Data!$O$2:$O$3501,"Placed")/COUNTIF(Raw_Data!$H$2:$H$3501,">0"),"0.0%")&" vs "&TEXT(COUNTIFS(Raw_Data!$H$2:$H$3501,0,Raw_Data!$O$2:$O$3501,"Placed")/COUNTIF(Raw_Data!$H$2:$H$3501,0),"0.0%") -> 81.0% vs 72.2%
A60: Placement rate – students WITH certifications vs WITHOUT: | H60: =TEXT(COUNTIFS(Raw_Data!$I$2:$I$3501,">0",Raw_Data!$O$2:$O$3501,"Placed")/COUNTIF(Raw_Data!$I$2:$I$3501,">0"),"0.0%")&" vs "&TEXT(COUNTIFS(Raw_Data!$I$2:$I$3501,0,Raw_Data!$O$2:$O$3501,"Placed")/COUNTIF(Raw_Data!$I$2:$I$3501,0),"0.0%") -> 79.8% vs 77.1%
A61: Average CGPA – Placed students vs Unplaced students: | H61: =TEXT(AVERAGEIF(Raw_Data!$O$2:$O$3501,"Placed",Raw_Data!$F$2:$F$3501),"0.00")&" vs "&TEXT(AVERAGEIF(Raw_Data!$O$2:$O$3501,"Unplaced",Raw_Data!$F$2:$F$3501),"0.00") -> 7.76 vs 7.26
A62: Students who received multiple offers (>1): | H62: =COUNTIF(Raw_Data!$U$2:$U$3501,">1")&" students out of "&COUNTA(Raw_Data!$A$2:$A$3501) -> 1085 students out of 3500

Sheet Raw_Data
A1: Student_ID | B1: Academic_Year | C1: Department | D1: Gender | E1: Age | F1: CGPA | G1: Attendance_Percentage | H1: Internship_Count | I1: Certifications | J1: Projects_Completed | K1: Aptitude_Score | L1: Technical_Score | M1: HR_Score | N1: Backlogs | O1: Placement_Status | P1: Company | Q1: Industry | R1: Job_Role | S1: Package_LPA | T1: Placement_Date | U1: Offer_Count | V1: Placement_Year | X1: CGPA_Key | Y1: Package_Key | Z1: Technical_Key
A2: STU10001 | B2: 2024-25 | C2: CSE | D2: Male | E2: 22 | F2: 6.54 | G2: 93.5 | H2: 1 | I2: 1 | J2: 6 | K2: 60.5 | L2: 97.7 | M2: 71.6 | N2: 1 | O2: Placed | P2: Microsoft | Q2: Software Product | R2: Business Analyst | S2: 19.83 | T2: 45505 | U2: 2 | V2: 2024 | X2: =F2-ROW()*0.0000001 -> 6.5399998 | Y2: =S2-ROW()*0.0000001 -> 19.83 | Z2: =L2-ROW()*0.0000001 -> 97.7
A3: STU10002 | B3: 2025-26 | C3: CSE | D3: Male | E3: 20 | F3: 6.16 | G3: 62.3 | H3: 1 | I3: 0 | J3: 6 | K3: 59.3 | L3: 88.1 | M3: 50.8 | N3: 0 | O3: Unplaced | P3: Not Placed | S3: 0 | U3: 0 | V3: 2025 | X3: =F3-ROW()*0.0000001 -> 6.1599997 | Y3: =S3-ROW()*0.0000001 -> -3e-07 | Z3: =L3-ROW()*0.0000001 -> 88.1
A4: STU10003 | B4: 2023-24 | C4: ECE | D4: Female | E4: 22 | F4: 7.27 | G4: 72.6 | H4: 2 | I4: 1 | J4: 5 | K4: 44.9 | L4: 57.8 | M4: 68.8 | N4: 1 | O4: Placed | P4: TCS | Q4: IT Services | R4: Full Stack Developer | S4: 5.07 | T4: 45187 | U4: 1 | V4: 2023 | X4: =F4-ROW()*0.0000001 -> 7.2699996 | Y4: =S4-ROW()*0.0000001 -> 5.0699996 | Z4: =L4-ROW()*0.0000001 -> 57.8
A5: STU10004 | B5: 2025-26 | C5: IT | D5: Male | E5: 21 | F5: 6.63 | G5: 72.9 | H5: 1 | I5: 3 | J5: 6 | K5: 80.2 | L5: 79.1 | M5: 76.4 | N5: 0 | O5: Placed | P5: Wipro | Q5: IT Services | R5: Data Analyst | S5: 5.25 | T5: 45873 | U5: 1 | V5: 2025 | X5: =F5-ROW()*0.0000001 -> 6.6299995 | Y5: =S5-ROW()*0.0000001 -> 5.2499995 | Z5: =L5-ROW()*0.0000001 -> 79.099999
A6: STU10005 | B6: 2025-26 | C6: MECH | D6: Female | E6: 22 | F6: 8.15 | G6: 81.5 | H6: 1 | I6: 2 | J6: 2 | K6: 50.4 | L6: 56.8 | M6: 84.4 | N6: 0 | O6: Placed | P6: Infosys | Q6: IT Services | R6: Cloud Engineer | S6: 6.64 | T6: 45891 | U6: 1 | V6: 2025 | X6: =F6-ROW()*0.0000001 -> 8.1499994 | Y6: =S6-ROW()*0.0000001 -> 6.6399994 | Z6: =L6-ROW()*0.0000001 -> 56.799999
A7: STU10006 | B7: 2022-23 | C7: IT | D7: Male | E7: 22 | F7: 8.16 | G7: 65.3 | H7: 1 | I7: 2 | J7: 6 | K7: 57.9 | L7: 57.8 | M7: 64.6 | N7: 0 | O7: Placed | P7: TCS | Q7: IT Services | R7: Cloud Engineer | S7: 6.19 | T7: 44861 | U7: 1 | V7: 2022 | X7: =F7-ROW()*0.0000001 -> 8.1599993 | Y7: =S7-ROW()*0.0000001 -> 6.1899993 | Z7: =L7-ROW()*0.0000001 -> 57.799999
A8: STU10007 | B8: 2023-24 | C8: AIML | D8: Female | E8: 23 | F8: 7.52 | G8: 91.9 | H8: 1 | I8: 2 | J8: 2 | K8: 54.7 | L8: 63.4 | M8: 76.1 | N8: 0 | O8: Placed | P8: Microsoft | Q8: Software Product | R8: Software Engineer | S8: 19.58 | T8: 45193 | U8: 1 | V8: 2023 | X8: =F8-ROW()*0.0000001 -> 7.5199992 | Y8: =S8-ROW()*0.0000001 -> 19.579999 | Z8: =L8-ROW()*0.0000001 -> 63.399999
A9: STU10008 | B9: 2023-24 | C9: AIML | D9: Female | E9: 22 | F9: 8.24 | G9: 64.1 | H9: 1 | I9: 0 | J9: 3 | K9: 79.7 | L9: 60.9 | M9: 77.3 | N9: 0 | O9: Placed | P9: Cognizant | Q9: IT Services | R9: Data Analyst | S9: 6.47 | T9: 45170 | U9: 1 | V9: 2023 | X9: =F9-ROW()*0.0000001 -> 8.2399991 | Y9: =S9-ROW()*0.0000001 -> 6.4699991 | Z9: =L9-ROW()*0.0000001 -> 60.899999
A10: STU10009 | B10: 2023-24 | C10: EEE | D10: Female | E10: 23 | F10: 7.71 | G10: 91.3 | H10: 1 | I10: 1 | J10: 3 | K10: 59.8 | L10: 46.6 | M10: 52.5 | N10: 2 | O10: Placed | P10: IBM | Q10: Software Product | R10: Data Analyst | S10: 7.62 | T10: 45248 | U10: 1 | V10: 2023 | X10: =F10-ROW()*0.0000001 -> 7.709999 | Y10: =S10-ROW()*0.0000001 -> 7.619999 | Z10: =L10-ROW()*0.0000001 -> 46.599999
A11: STU10010 | B11: 2025-26 | C11: AIML | D11: Female | E11: 21 | F11: 9.33 | G11: 89.8 | H11: 1 | I11: 1 | J11: 6 | K11: 81.5 | L11: 89.9 | M11: 58.9 | N11: 0 | O11: Placed | P11: Deloitte | Q11: Consulting | R11: Data Analyst | S11: 11.56 | T11: 45935 | U11: 3 | V11: 2025 | X11: =F11-ROW()*0.0000001 -> 9.3299989 | Y11: =S11-ROW()*0.0000001 -> 11.559999 | Z11: =L11-ROW()*0.0000001 -> 89.899999
A12: STU10011 | B12: 2024-25 | C12: MECH | D12: Male | E12: 20 | F12: 8.21 | G12: 72.2 | H12: 2 | I12: 1 | J12: 4 | K12: 76.2 | L12: 73.2 | M12: 80 | N12: 0 | O12: Placed | P12: Capgemini | Q12: Consulting | R12: Business Analyst | S12: 6.72 | T12: 45604 | U12: 1 | V12: 2024 | X12: =F12-ROW()*0.0000001 -> 8.2099988 | Y12: =S12-ROW()*0.0000001 -> 6.7199988 | Z12: =L12-ROW()*0.0000001 -> 73.199999
A13: STU10012 | B13: 2023-24 | C13: ECE | D13: Female | E13: 23 | F13: 8.46 | G13: 93.4 | H13: 2 | I13: 4 | J13: 4 | K13: 54.8 | L13: 93.3 | M13: 74.7 | N13: 0 | O13: Unplaced | P13: Not Placed | S13: 0 | U13: 0 | V13: 2023 | X13: =F13-ROW()*0.0000001 -> 8.4599987 | Y13: =S13-ROW()*0.0000001 -> -1.3e-06 | Z13: =L13-ROW()*0.0000001 -> 93.299999
A14: STU10013 | B14: 2025-26 | C14: CSE | D14: Female | E14: 22 | F14: 6.35 | G14: 79 | H14: 2 | I14: 2 | J14: 6 | K14: 66.6 | L14: 67.5 | M14: 75.1 | N14: 0 | O14: Placed | P14: Capgemini | Q14: Consulting | R14: Full Stack Developer | S14: 6.05 | T14: 45989 | U14: 1 | V14: 2025 | X14: =F14-ROW()*0.0000001 -> 6.3499986 | Y14: =S14-ROW()*0.0000001 -> 6.0499986 | Z14: =L14-ROW()*0.0000001 -> 67.499999
A15: STU10014 | B15: 2022-23 | C15: ECE | D15: Female | E15: 22 | F15: 6.6 | G15: 76.7 | H15: 1 | I15: 3 | J15: 4 | K15: 44.2 | L15: 48 | M15: 62.8 | N15: 0 | O15: Placed | P15: Microsoft | Q15: Software Product | R15: Business Analyst | S15: 17.79 | T15: 44844 | U15: 2 | V15: 2022 | X15: =F15-ROW()*0.0000001 -> 6.5999985 | Y15: =S15-ROW()*0.0000001 -> 17.789998 | Z15: =L15-ROW()*0.0000001 -> 47.999998
A16: STU10015 | B16: 2024-25 | C16: EEE | D16: Female | E16: 23 | F16: 8.08 | G16: 78.2 | H16: 0 | I16: 1 | J16: 4 | K16: 73.6 | L16: 85.4 | M16: 56.6 | N16: 1 | O16: Placed | P16: Wipro | Q16: IT Services | R16: Cloud Engineer | S16: 5.84 | T16: 45604 | U16: 2 | V16: 2024 | X16: =F16-ROW()*0.0000001 -> 8.0799984 | Y16: =S16-ROW()*0.0000001 -> 5.8399984 | Z16: =L16-ROW()*0.0000001 -> 85.399998
A17: STU10016 | B17: 2022-23 | C17: CIVIL | D17: Female | E17: 21 | F17: 6.26 | G17: 79 | H17: 1 | I17: 1 | J17: 1 | K17: 58.8 | L17: 73.9 | M17: 79.7 | N17: 0 | O17: Unplaced | P17: Not Placed | S17: 0 | U17: 0 | V17: 2022 | X17: =F17-ROW()*0.0000001 -> 6.2599983 | Y17: =S17-ROW()*0.0000001 -> -1.7e-06 | Z17: =L17-ROW()*0.0000001 -> 73.899998
A18: STU10017 | B18: 2024-25 | C18: ECE | D18: Female | E18: 20 | F18: 7.09 | G18: 79.8 | H18: 2 | I18: 1 | J18: 5 | K18: 53.2 | L18: 66 | M18: 76 | N18: 1 | O18: Unplaced | P18: Not Placed | S18: 0 | U18: 0 | V18: 2024 | X18: =F18-ROW()*0.0000001 -> 7.0899982 | Y18: =S18-ROW()*0.0000001 -> -1.8e-06 | Z18: =L18-ROW()*0.0000001 -> 65.999998
A19: STU10018 | B19: 2025-26 | C19: AIML | D19: Male | E19: 22 | F19: 8.71 | G19: 80 | H19: 1 | I19: 3 | J19: 6 | K19: 64.2 | L19: 88.1 | M19: 50.7 | N19: 0 | O19: Placed | P19: Amazon | Q19: E-commerce | R19: Software Engineer | S19: 15.55 | T19: 45877 | U19: 1 | V19: 2025 | X19: =F19-ROW()*0.0000001 -> 8.7099981 | Y19: =S19-ROW()*0.0000001 -> 15.549998 | Z19: =L19-ROW()*0.0000001 -> 88.099998
A20: STU10019 | B20: 2021-22 | C20: MECH | D20: Female | E20: 21 | F20: 7.07 | G20: 74 | H20: 1 | I20: 1 | J20: 6 | K20: 61.5 | L20: 49.9 | M20: 72.8 | N20: 1 | O20: Placed | P20: Deloitte | Q20: Consulting | R20: Business Analyst | S20: 7.91 | T20: 44444 | U20: 1 | V20: 2021 | X20: =F20-ROW()*0.0000001 -> 7.069998 | Y20: =S20-ROW()*0.0000001 -> 7.909998 | Z20: =L20-ROW()*0.0000001 -> 49.899998
A21: STU10020 | B21: 2024-25 | C21: CSE | D21: Male | E21: 20 | F21: 6.56 | G21: 76.1 | H21: 1 | I21: 2 | J21: 3 | K21: 72 | L21: 84.7 | M21: 95.4 | N21: 0 | O21: Placed | P21: IBM | Q21: Software Product | R21: QA Engineer | S21: 7.43 | T21: 45611 | U21: 1 | V21: 2024 | X21: =F21-ROW()*0.0000001 -> 6.5599979 | Y21: =S21-ROW()*0.0000001 -> 7.4299979 | Z21: =L21-ROW()*0.0000001 -> 84.699998
A22: STU10021 | B22: 2022-23 | C22: AIML | D22: Male | E22: 20 | F22: 8.25 | G22: 76.9 | H22: 3 | I22: 3 | J22: 3 | K22: 94.6 | L22: 80.8 | M22: 81.2 | N22: 2 | O22: Placed | P22: Deloitte | Q22: Consulting | R22: QA Engineer | S22: 10.24 | T22: 44785 | U22: 2 | V22: 2022 | X22: =F22-ROW()*0.0000001 -> 8.2499978 | Y22: =S22-ROW()*0.0000001 -> 10.239998 | Z22: =L22-ROW()*0.0000001 -> 80.799998
A23: STU10022 | B23: 2025-26 | C23: ECE | D23: Male | E23: 22 | F23: 9.52 | G23: 97.1 | H23: 3 | I23: 5 | J23: 3 | K23: 86.5 | L23: 73.5 | M23: 63.3 | N23: 1 | O23: Placed | P23: Accenture | Q23: Consulting | R23: Business Analyst | S23: 7.88 | T23: 45897 | U23: 1 | V23: 2025 | X23: =F23-ROW()*0.0000001 -> 9.5199977 | Y23: =S23-ROW()*0.0000001 -> 7.8799977 | Z23: =L23-ROW()*0.0000001 -> 73.499998
A24: STU10023 | B24: 2024-25 | C24: IT | D24: Male | E24: 23 | F24: 6.92 | G24: 76.9 | H24: 0 | I24: 1 | J24: 3 | K24: 51.3 | L24: 47.8 | M24: 76 | N24: 0 | O24: Placed | P24: TCS | Q24: IT Services | R24: Full Stack Developer | S24: 4.14 | T24: 45506 | U24: 1 | V24: 2024 | X24: =F24-ROW()*0.0000001 -> 6.9199976 | Y24: =S24-ROW()*0.0000001 -> 4.1399976 | Z24: =L24-ROW()*0.0000001 -> 47.799998
A25: STU10024 | B25: 2021-22 | C25: EEE | D25: Male | E25: 22 | F25: 8.75 | G25: 76.3 | H25: 2 | I25: 0 | J25: 3 | K25: 89.5 | L25: 84.1 | M25: 71.5 | N25: 0 | O25: Placed | P25: Wipro | Q25: IT Services | R25: Software Engineer | S25: 7.73 | T25: 44519 | U25: 1 | V25: 2021 | X25: =F25-ROW()*0.0000001 -> 8.7499975 | Y25: =S25-ROW()*0.0000001 -> 7.7299975 | Z25: =L25-ROW()*0.0000001 -> 84.099998
A26: STU10025 | B26: 2021-22 | C26: CSE | D26: Male | E26: 22 | F26: 6.81 | G26: 95.6 | H26: 0 | I26: 1 | J26: 4 | K26: 68.7 | L26: 81.2 | M26: 93.8 | N26: 2 | O26: Placed | P26: Amazon | Q26: E-commerce | R26: Full Stack Developer | S26: 14.83 | T26: 44486 | U26: 1 | V26: 2021 | X26: =F26-ROW()*0.0000001 -> 6.8099974 | Y26: =S26-ROW()*0.0000001 -> 14.829997 | Z26: =L26-ROW()*0.0000001 -> 81.199997
A27: STU10026 | B27: 2023-24 | C27: EEE | D27: Male | E27: 22 | F27: 7.55 | G27: 79.1 | H27: 1 | I27: 3 | J27: 5 | K27: 32.4 | L27: 74 | M27: 60.5 | N27: 0 | O27: Placed | P27: Wipro | Q27: IT Services | R27: Data Analyst | S27: 5.6 | T27: 45157 | U27: 1 | V27: 2023 | X27: =F27-ROW()*0.0000001 -> 7.5499973 | Y27: =S27-ROW()*0.0000001 -> 5.5999973 | Z27: =L27-ROW()*0.0000001 -> 73.999997
A28: STU10027 | B28: 2023-24 | C28: ECE | D28: Male | E28: 21 | F28: 7.59 | G28: 74 | H28: 0 | I28: 1 | J28: 6 | K28: 64.8 | L28: 69.2 | M28: 89.6 | N28: 0 | O28: Placed | P28: TCS | Q28: IT Services | R28: Cloud Engineer | S28: 5.01 | T28: 45223 | U28: 1 | V28: 2023 | X28: =F28-ROW()*0.0000001 -> 7.5899972 | Y28: =S28-ROW()*0.0000001 -> 5.0099972 | Z28: =L28-ROW()*0.0000001 -> 69.199997
A29: STU10028 | B29: 2022-23 | C29: IT | D29: Male | E29: 23 | F29: 6.95 | G29: 72 | H29: 0 | I29: 2 | J29: 2 | K29: 46.2 | L29: 53.1 | M29: 59.7 | N29: 0 | O29: Unplaced | P29: Not Placed | S29: 0 | U29: 0 | V29: 2022 | X29: =F29-ROW()*0.0000001 -> 6.9499971 | Y29: =S29-ROW()*0.0000001 -> -2.9e-06 | Z29: =L29-ROW()*0.0000001 -> 53.099997
A30: STU10029 | B30: 2024-25 | C30: AIML | D30: Female | E30: 21 | F30: 8.44 | G30: 69.2 | H30: 0 | I30: 2 | J30: 3 | K30: 61.9 | L30: 53.2 | M30: 78 | N30: 1 | O30: Placed | P30: Cognizant | Q30: IT Services | R30: Business Analyst | S30: 6.54 | T30: 45553 | U30: 3 | V30: 2024 | X30: =F30-ROW()*0.0000001 -> 8.439997 | Y30: =S30-ROW()*0.0000001 -> 6.539997 | Z30: =L30-ROW()*0.0000001 -> 53.199997
A31: STU10030 | B31: 2024-25 | C31: ECE | D31: Female | E31: 22 | F31: 6.26 | G31: 86.9 | H31: 3 | I31: 1 | J31: 3 | K31: 94.7 | L31: 58.4 | M31: 81.7 | N31: 3 | O31: Placed | P31: IBM | Q31: Software Product | R31: Software Engineer | S31: 6.36 | T31: 45616 | U31: 1 | V31: 2024 | X31: =F31-ROW()*0.0000001 -> 6.2599969 | Y31: =S31-ROW()*0.0000001 -> 6.3599969 | Z31: =L31-ROW()*0.0000001 -> 58.399997
A32: STU10031 | B32: 2023-24 | C32: CSE | D32: Female | E32: 23 | F32: 7.83 | G32: 65.8 | H32: 2 | I32: 0 | J32: 3 | K32: 49.7 | L32: 46.4 | M32: 87.8 | N32: 0 | O32: Placed | P32: Microsoft | Q32: Software Product | R32: Software Engineer | S32: 19.32 | T32: 45175 | U32: 2 | V32: 2023 | X32: =F32-ROW()*0.0000001 -> 7.8299968 | Y32: =S32-ROW()*0.0000001 -> 19.319997 | Z32: =L32-ROW()*0.0000001 -> 46.399997
A33: STU10032 | B33: 2024-25 | C33: ECE | D33: Female | E33: 20 | F33: 8.62 | G33: 94.1 | H33: 0 | I33: 1 | J33: 3 | K33: 49.2 | L33: 46.9 | M33: 83.2 | N33: 0 | O33: Placed | P33: Deloitte | Q33: Consulting | R33: Full Stack Developer | S33: 7.99 | T33: 45556 | U33: 2 | V33: 2024 | X33: =F33-ROW()*0.0000001 -> 8.6199967 | Y33: =S33-ROW()*0.0000001 -> 7.9899967 | Z33: =L33-ROW()*0.0000001 -> 46.899997
A34: STU10033 | B34: 2024-25 | C34: AIML | D34: Female | E34: 23 | F34: 8.36 | G34: 81.2 | H34: 1 | I34: 1 | J34: 3 | K34: 66.6 | L34: 63.3 | M34: 55.7 | N34: 1 | O34: Placed | P34: Accenture | Q34: Consulting | R34: Data Analyst | S34: 7.48 | T34: 45589 | U34: 1 | V34: 2024 | X34: =F34-ROW()*0.0000001 -> 8.3599966 | Y34: =S34-ROW()*0.0000001 -> 7.4799966 | Z34: =L34-ROW()*0.0000001 -> 63.299997
A35: STU10034 | B35: 2021-22 | C35: CSE | D35: Male | E35: 22 | F35: 8.09 | G35: 78.1 | H35: 1 | I35: 1 | J35: 6 | K35: 56.6 | L35: 50 | M35: 74 | N35: 3 | O35: Unplaced | P35: Not Placed | S35: 0 | U35: 0 | V35: 2021 | X35: =F35-ROW()*0.0000001 -> 8.0899965 | Y35: =S35-ROW()*0.0000001 -> -3.5e-06 | Z35: =L35-ROW()*0.0000001 -> 49.999997
A36: STU10035 | B36: 2023-24 | C36: CSE | D36: Female | E36: 23 | F36: 9.08 | G36: 79.9 | H36: 1 | I36: 2 | J36: 3 | K36: 64.4 | L36: 66.5 | M36: 80.1 | N36: 0 | O36: Placed | P36: IBM | Q36: Software Product | R36: Full Stack Developer | S36: 8.35 | T36: 45198 | U36: 3 | V36: 2023 | X36: =F36-ROW()*0.0000001 -> 9.0799964 | Y36: =S36-ROW()*0.0000001 -> 8.3499964 | Z36: =L36-ROW()*0.0000001 -> 66.499996
A37: STU10036 | B37: 2025-26 | C37: CSE | D37: Female | E37: 20 | F37: 7.45 | G37: 86.2 | H37: 2 | I37: 2 | J37: 4 | K37: 69.5 | L37: 71 | M37: 87 | N37: 0 | O37: Placed | P37: Wipro | Q37: IT Services | R37: Full Stack Developer | S37: 6.65 | T37: 45966 | U37: 1 | V37: 2025 | X37: =F37-ROW()*0.0000001 -> 7.4499963 | Y37: =S37-ROW()*0.0000001 -> 6.6499963 | Z37: =L37-ROW()*0.0000001 -> 70.999996
A38: STU10037 | B38: 2023-24 | C38: CSE | D38: Male | E38: 20 | F38: 6.28 | G38: 77.8 | H38: 0 | I38: 0 | J38: 5 | K38: 47.3 | L38: 48.3 | M38: 60.4 | N38: 0 | O38: Unplaced | P38: Not Placed | S38: 0 | U38: 0 | V38: 2023 | X38: =F38-ROW()*0.0000001 -> 6.2799962 | Y38: =S38-ROW()*0.0000001 -> -3.8e-06 | Z38: =L38-ROW()*0.0000001 -> 48.299996
A39: STU10038 | B39: 2025-26 | C39: CIVIL | D39: Male | E39: 23 | F39: 7.77 | G39: 80.3 | H39: 2 | I39: 2 | J39: 4 | K39: 71.2 | L39: 82.4 | M39: 62.7 | N39: 0 | O39: Unplaced | P39: Not Placed | S39: 0 | U39: 0 | V39: 2025 | X39: =F39-ROW()*0.0000001 -> 7.7699961 | Y39: =S39-ROW()*0.0000001 -> -3.9e-06 | Z39: =L39-ROW()*0.0000001 -> 82.399996
A40: STU10039 | B40: 2021-22 | C40: MECH | D40: Female | E40: 20 | F40: 7.54 | G40: 91.5 | H40: 1 | I40: 1 | J40: 4 | K40: 57.3 | L40: 85.2 | M40: 56.4 | N40: 3 | O40: Placed | P40: TCS | Q40: IT Services | R40: DevOps Engineer | S40: 6.39 | T40: 44450 | U40: 1 | V40: 2021 | X40: =F40-ROW()*0.0000001 -> 7.539996 | Y40: =S40-ROW()*0.0000001 -> 6.389996 | Z40: =L40-ROW()*0.0000001 -> 85.199996
...

Sheet Data_Cleaning
A1: DATA CLEANING & QUALITY REPORT
A3: Data Quality Summary
A4: Metric | B4: Value
A5: Total Records | B5: =COUNTA(Raw_Data!$A$2:$A$3501) -> 3500
A6: Duplicate Student IDs | B6: =SUMPRODUCT((COUNTIF(Raw_Data!$A$2:$A$3501,Raw_Data!$A$2:$A$3501)>1)*1) -> 0
A7: Missing Values (Industry) | B7: =COUNTBLANK(Raw_Data!$Q$2:$Q$3501) -> 720
A8: Missing Values (Job Role) | B8: =COUNTBLANK(Raw_Data!$R$2:$R$3501) -> 720
A9: Missing Values (Placement Date) | B9: =COUNTBLANK(Raw_Data!$T$2:$T$3501) -> 720
A10: Total Missing Values | B10: =B7+B8+B9 -> 2160
A11: Placed Students | B11: =COUNTIF(Raw_Data!$O$2:$O$3501,"Placed") -> 2780
A12: Unplaced Students | B12: =COUNTIF(Raw_Data!$O$2:$O$3501,"Unplaced") -> 720
A13: CGPA Out of Range (<0 or >10) | B13: =COUNTIFS(Raw_Data!$F$2:$F$3501,"<0")+COUNTIFS(Raw_Data!$F$2:$F$3501,">10") -> 0
A14: Attendance Out of Range (<0 or >100) | B14: =COUNTIFS(Raw_Data!$G$2:$G$3501,"<0")+COUNTIFS(Raw_Data!$G$2:$G$3501,">100") -> 0
A17: Cleaning Notes
A18: • No duplicate Student IDs were found in the dataset (3,500 unique records).
A19: • Missing values in Industry, Job_Role and Placement_Date are EXPECTED: these fields are
A20: only populated for students with Placement_Status = 'Placed'. No correction needed.
A21: • All numeric fields (CGPA, Attendance %, Scores) fall within valid expected ranges.
A22: • Data types verified: dates recognised as dates, numeric fields stored as numbers, text
A23: fields consistent (no stray capitalisation/whitespace variants detected).
A24: • Original Raw_Data sheet has been preserved unmodified; this sheet only reports on it.

Sheet Summary
A1: KPI / SUMMARY SHEET — College Placement Analytics
A2: KPI | B2: Value | D2: All KPIs are formula-driven off Raw_Data and recalculate automatically when the data changes.
A3: Total Students | B3: =COUNTA(Raw_Data!$A$2:$A$3501) -> 3500
A4: Placed Students | B4: =COUNTIF(Raw_Data!$O$2:$O$3501,"Placed") -> 2780
A5: Unplaced Students | B5: =COUNTIF(Raw_Data!$O$2:$O$3501,"Unplaced") -> 720
A6: Placement Rate | B6: =B4/B3 -> 0.79428571
A7: Average Package (LPA) | B7: =AVERAGEIF(Raw_Data!$O$2:$O$3501,"Placed",Raw_Data!$S$2:$S$3501) -> 9.1315899
A8: Highest Package (LPA) | B8: =MAX(Raw_Data!$S$2:$S$3501) -> 23.34
A9: Lowest Package (LPA, Placed only) | B9: =_xlfn.MINIFS(Raw_Data!$S$2:$S$3501,Raw_Data!$O$2:$O$3501,"Placed") -> 3
A10: Total Offers | B10: =SUM(Raw_Data!$U$2:$U$3501) -> 4181
A11: Average CGPA | B11: =AVERAGE(Raw_Data!$F$2:$F$3501) -> 7.65676
A12: Average Attendance (%) | B12: =AVERAGE(Raw_Data!$G$2:$G$3501) -> 81.926543
A13: Total Recruiters (Companies) | B13: =SUMPRODUCT((Raw_Data!$P$2:$P$3501<>"Not Placed")*(MATCH(Raw_Data!$P$2:$P$3501,Raw_Data!$P$2:$P$3501,0)=ROW(Raw_Data!$P$2:$P$3501)-1)) -> 10
A14: Students with Internships | B14: =COUNTIF(Raw_Data!$H$2:$H$3501,">0") -> 2888
A15: Students with Certifications | B15: =COUNTIF(Raw_Data!$I$2:$I$3501,">0") -> 2985
A16: Average Aptitude Score | B16: =AVERAGE(Raw_Data!$K$2:$K$3501) -> 67.876286
A17: Average Technical Score | B17: =AVERAGE(Raw_Data!$L$2:$L$3501) -> 69.938914
A18: Average HR Score | B18: =AVERAGE(Raw_Data!$M$2:$M$3501) -> 73.703514

Sheet Pivot_Tables
A1: PIVOT-STYLE SUMMARY TABLES & CHARTS (formula-driven, live off Raw_Data)
A3: Pivot 1: Placement Status
A4: Status | B4: Count of Student_ID
A5: Placed | B5: =COUNTIF(Raw_Data!$O$2:$O$3501,"Placed") -> 2780
A6: Unplaced | B6: =COUNTIF(Raw_Data!$O$2:$O$3501,"Unplaced") -> 720
A7: Total | B7: =SUM(B5:B6) -> 3500
A23: Pivot 2: Department-wise Placement
A24: Department | B24: Placed | C24: Unplaced | D24: Total | E24: Placement Rate
A25: AIML | B25: =COUNTIFS(Raw_Data!$C$2:$C$3501,"AIML",Raw_Data!$O$2:$O$3501,"Placed") -> 308 | C25: =COUNTIFS(Raw_Data!$C$2:$C$3501,"AIML",Raw_Data!$O$2:$O$3501,"Unplaced") -> 86 | D25: =B25+C25 -> 394 | E25: =B25/D25 -> 0.78172589
A26: CIVIL | B26: =COUNTIFS(Raw_Data!$C$2:$C$3501,"CIVIL",Raw_Data!$O$2:$O$3501,"Placed") -> 291 | C26: =COUNTIFS(Raw_Data!$C$2:$C$3501,"CIVIL",Raw_Data!$O$2:$O$3501,"Unplaced") -> 78 | D26: =B26+C26 -> 369 | E26: =B26/D26 -> 0.78861789
A27: CSE | B27: =COUNTIFS(Raw_Data!$C$2:$C$3501,"CSE",Raw_Data!$O$2:$O$3501,"Placed") -> 708 | C27: =COUNTIFS(Raw_Data!$C$2:$C$3501,"CSE",Raw_Data!$O$2:$O$3501,"Unplaced") -> 186 | D27: =B27+C27 -> 894 | E27: =B27/D27 -> 0.79194631
A28: ECE | B28: =COUNTIFS(Raw_Data!$C$2:$C$3501,"ECE",Raw_Data!$O$2:$O$3501,"Placed") -> 419 | C28: =COUNTIFS(Raw_Data!$C$2:$C$3501,"ECE",Raw_Data!$O$2:$O$3501,"Unplaced") -> 126 | D28: =B28+C28 -> 545 | E28: =B28/D28 -> 0.76880734
A29: EEE | B29: =COUNTIFS(Raw_Data!$C$2:$C$3501,"EEE",Raw_Data!$O$2:$O$3501,"Placed") -> 270 | C29: =COUNTIFS(Raw_Data!$C$2:$C$3501,"EEE",Raw_Data!$O$2:$O$3501,"Unplaced") -> 59 | D29: =B29+C29 -> 329 | E29: =B29/D29 -> 0.82066869
A30: IT | B30: =COUNTIFS(Raw_Data!$C$2:$C$3501,"IT",Raw_Data!$O$2:$O$3501,"Placed") -> 439 | C30: =COUNTIFS(Raw_Data!$C$2:$C$3501,"IT",Raw_Data!$O$2:$O$3501,"Unplaced") -> 116 | D30: =B30+C30 -> 555 | E30: =B30/D30 -> 0.79099099
A31: MECH | B31: =COUNTIFS(Raw_Data!$C$2:$C$3501,"MECH",Raw_Data!$O$2:$O$3501,"Placed") -> 345 | C31: =COUNTIFS(Raw_Data!$C$2:$C$3501,"MECH",Raw_Data!$O$2:$O$3501,"Unplaced") -> 69 | D31: =B31+C31 -> 414 | E31: =B31/D31 -> 0.83333333
A32: Total | B32: =SUM(B25:B31) -> 2780 | C32: =SUM(C25:C31) -> 720 | D32: =SUM(D25:D31) -> 3500
A43: Pivot 3: Academic Year Placement
A44: Academic_Year | B44: Count of Student_ID | C44: Placement Rate
A45: 2021-22 | B45: =COUNTIF(Raw_Data!$B$2:$B$3501,"2021-22") -> 718 | C45: =COUNTIFS(Raw_Data!$B$2:$B$3501,"2021-22",Raw_Data!$O$2:$O$3501,"Placed")/COUNTIF(Raw_Data!$B$2:$B$3501,"2021-22") -> 0.79526462
A46: 2022-23 | B46: =COUNTIF(Raw_Data!$B$2:$B$3501,"2022-23") -> 673 | C46: =COUNTIFS(Raw_Data!$B$2:$B$3501,"2022-23",Raw_Data!$O$2:$O$3501,"Placed")/COUNTIF(Raw_Data!$B$2:$B$3501,"2022-23") -> 0.79197623
A47: 2023-24 | B47: =COUNTIF(Raw_Data!$B$2:$B$3501,"2023-24") -> 666 | C47: =COUNTIFS(Raw_Data!$B$2:$B$3501,"2023-24",Raw_Data!$O$2:$O$3501,"Placed")/COUNTIF(Raw_Data!$B$2:$B$3501,"2023-24") -> 0.81081081
A48: 2024-25 | B48: =COUNTIF(Raw_Data!$B$2:$B$3501,"2024-25") -> 727 | C48: =COUNTIFS(Raw_Data!$B$2:$B$3501,"2024-25",Raw_Data!$O$2:$O$3501,"Placed")/COUNTIF(Raw_Data!$B$2:$B$3501,"2024-25") -> 0.77991747
A49: 2025-26 | B49: =COUNTIF(Raw_Data!$B$2:$B$3501,"2025-26") -> 716 | C49: =COUNTIFS(Raw_Data!$B$2:$B$3501,"2025-26",Raw_Data!$O$2:$O$3501,"Placed")/COUNTIF(Raw_Data!$B$2:$B$3501,"2025-26") -> 0.79469274
A63: Pivot 4: Company Hiring
A64: Company | B64: Count of Student_ID
A65: Accenture | B65: =COUNTIF(Raw_Data!$P$2:$P$3501,"Accenture") -> 298
A66: Amazon | B66: =COUNTIF(Raw_Data!$P$2:$P$3501,"Amazon") -> 265
A67: Capgemini | B67: =COUNTIF(Raw_Data!$P$2:$P$3501,"Capgemini") -> 264
A68: Cognizant | B68: =COUNTIF(Raw_Data!$P$2:$P$3501,"Cognizant") -> 270
A69: Deloitte | B69: =COUNTIF(Raw_Data!$P$2:$P$3501,"Deloitte") -> 249
A70: IBM | B70: =COUNTIF(Raw_Data!$P$2:$P$3501,"IBM") -> 270
A71: Infosys | B71: =COUNTIF(Raw_Data!$P$2:$P$3501,"Infosys") -> 293
A72: Microsoft | B72: =COUNTIF(Raw_Data!$P$2:$P$3501,"Microsoft") -> 297
A73: TCS | B73: =COUNTIF(Raw_Data!$P$2:$P$3501,"TCS") -> 293
A74: Wipro | B74: =COUNTIF(Raw_Data!$P$2:$P$3501,"Wipro") -> 281
A83: Pivot 5: Department Average Package
A84: Department | B84: Average Package_LPA
A85: AIML | B85: =AVERAGEIFS(Raw_Data!$S$2:$S$3501,Raw_Data!$C$2:$C$3501,"AIML",Raw_Data!$O$2:$O$3501,"Placed") -> 9.2163961
A86: CIVIL | B86: =AVERAGEIFS(Raw_Data!$S$2:$S$3501,Raw_Data!$C$2:$C$3501,"CIVIL",Raw_Data!$O$2:$O$3501,"Placed") -> 9.3270447
A87: CSE | B87: =AVERAGEIFS(Raw_Data!$S$2:$S$3501,Raw_Data!$C$2:$C$3501,"CSE",Raw_Data!$O$2:$O$3501,"Placed") -> 9.0775565
...

Sheet Salary_Analysis
A1: SALARY / PACKAGE ANALYSIS
E2: Total Placed (for %): | F2: =COUNTIF(Raw_Data!$O$2:$O$3501,"Placed") -> 2780
A3: Package Band Distribution (Placed Students)
A4: Package Band | B4: Number of Students | C4: Percentage
A5: 0-3 LPA | B5: =COUNTIFS(Raw_Data!$O$2:$O$3501,"Placed",Raw_Data!$S$2:$S$3501,">="&0,Raw_Data!$S$2:$S$3501,"<"&3) -> 0 | C5: =B5/$F$2 -> 0
A6: 3-6 LPA | B6: =COUNTIFS(Raw_Data!$O$2:$O$3501,"Placed",Raw_Data!$S$2:$S$3501,">="&3,Raw_Data!$S$2:$S$3501,"<"&6) -> 597 | C6: =B6/$F$2 -> 0.2147482
A7: 6-10 LPA | B7: =COUNTIFS(Raw_Data!$O$2:$O$3501,"Placed",Raw_Data!$S$2:$S$3501,">="&6,Raw_Data!$S$2:$S$3501,"<"&10) -> 1547 | C7: =B7/$F$2 -> 0.55647482
A8: 10-15 LPA | B8: =COUNTIFS(Raw_Data!$O$2:$O$3501,"Placed",Raw_Data!$S$2:$S$3501,">="&10,Raw_Data!$S$2:$S$3501,"<"&15) -> 162 | C8: =B8/$F$2 -> 0.058273381
A9: 15-20 LPA | B9: =COUNTIFS(Raw_Data!$O$2:$O$3501,"Placed",Raw_Data!$S$2:$S$3501,">="&15,Raw_Data!$S$2:$S$3501,"<"&20) -> 370 | C9: =B9/$F$2 -> 0.13309353
A10: 20+ LPA | B10: =COUNTIFS(Raw_Data!$O$2:$O$3501,"Placed",Raw_Data!$S$2:$S$3501,">="&20) -> 104 | C10: =B10/$F$2 -> 0.037410072
A15: Average / Highest Package by Department
A16: Department | B16: Average Package (LPA) | C16: Highest Package (LPA)
A17: AIML | B17: =AVERAGEIFS(Raw_Data!$S$2:$S$3501,Raw_Data!$C$2:$C$3501,"AIML",Raw_Data!$O$2:$O$3501,"Placed") -> 9.2163961 | C17: =_xlfn.MAXIFS(Raw_Data!$S$2:$S$3501,Raw_Data!$C$2:$C$3501,"AIML") -> 22.13
A18: CIVIL | B18: =AVERAGEIFS(Raw_Data!$S$2:$S$3501,Raw_Data!$C$2:$C$3501,"CIVIL",Raw_Data!$O$2:$O$3501,"Placed") -> 9.3270447 | C18: =_xlfn.MAXIFS(Raw_Data!$S$2:$S$3501,Raw_Data!$C$2:$C$3501,"CIVIL") -> 22.18
A19: CSE | B19: =AVERAGEIFS(Raw_Data!$S$2:$S$3501,Raw_Data!$C$2:$C$3501,"CSE",Raw_Data!$O$2:$O$3501,"Placed") -> 9.0775565 | C19: =_xlfn.MAXIFS(Raw_Data!$S$2:$S$3501,Raw_Data!$C$2:$C$3501,"CSE") -> 21.59
A20: ECE | B20: =AVERAGEIFS(Raw_Data!$S$2:$S$3501,Raw_Data!$C$2:$C$3501,"ECE",Raw_Data!$O$2:$O$3501,"Placed") -> 9.3092601 | C20: =_xlfn.MAXIFS(Raw_Data!$S$2:$S$3501,Raw_Data!$C$2:$C$3501,"ECE") -> 23.34
A21: EEE | B21: =AVERAGEIFS(Raw_Data!$S$2:$S$3501,Raw_Data!$C$2:$C$3501,"EEE",Raw_Data!$O$2:$O$3501,"Placed") -> 8.7347778 | C21: =_xlfn.MAXIFS(Raw_Data!$S$2:$S$3501,Raw_Data!$C$2:$C$3501,"EEE") -> 21.75
A22: IT | B22: =AVERAGEIFS(Raw_Data!$S$2:$S$3501,Raw_Data!$C$2:$C$3501,"IT",Raw_Data!$O$2:$O$3501,"Placed") -> 8.9116173 | C22: =_xlfn.MAXIFS(Raw_Data!$S$2:$S$3501,Raw_Data!$C$2:$C$3501,"IT") -> 21.84
A23: MECH | B23: =AVERAGEIFS(Raw_Data!$S$2:$S$3501,Raw_Data!$C$2:$C$3501,"MECH",Raw_Data!$O$2:$O$3501,"Placed") -> 9.3765797 | C23: =_xlfn.MAXIFS(Raw_Data!$S$2:$S$3501,Raw_Data!$C$2:$C$3501,"MECH") -> 21.59
A25: Average / Highest Package by Company
A26: Company | B26: Average Package (LPA) | C26: Highest Package (LPA)
A27: Accenture | B27: =AVERAGEIF(Raw_Data!$P$2:$P$3501,"Accenture",Raw_Data!$S$2:$S$3501) -> 7.0176846 | C27: =_xlfn.MAXIFS(Raw_Data!$S$2:$S$3501,Raw_Data!$P$2:$P$3501,"Accenture") -> 9.96
A28: Amazon | B28: =AVERAGEIF(Raw_Data!$P$2:$P$3501,"Amazon",Raw_Data!$S$2:$S$3501) -> 15.484981 | C28: =_xlfn.MAXIFS(Raw_Data!$S$2:$S$3501,Raw_Data!$P$2:$P$3501,"Amazon") -> 18.9
A29: Capgemini | B29: =AVERAGEIF(Raw_Data!$P$2:$P$3501,"Capgemini",Raw_Data!$S$2:$S$3501) -> 6.8153788 | C29: =_xlfn.MAXIFS(Raw_Data!$S$2:$S$3501,Raw_Data!$P$2:$P$3501,"Capgemini") -> 10.25
A30: Cognizant | B30: =AVERAGEIF(Raw_Data!$P$2:$P$3501,"Cognizant",Raw_Data!$S$2:$S$3501) -> 6.4715185 | C30: =_xlfn.MAXIFS(Raw_Data!$S$2:$S$3501,Raw_Data!$P$2:$P$3501,"Cognizant") -> 9.46
A31: Deloitte | B31: =AVERAGEIF(Raw_Data!$P$2:$P$3501,"Deloitte",Raw_Data!$S$2:$S$3501) -> 9.0563855 | C31: =_xlfn.MAXIFS(Raw_Data!$S$2:$S$3501,Raw_Data!$P$2:$P$3501,"Deloitte") -> 11.76
A32: IBM | B32: =AVERAGEIF(Raw_Data!$P$2:$P$3501,"IBM",Raw_Data!$S$2:$S$3501) -> 8.4452963 | C32: =_xlfn.MAXIFS(Raw_Data!$S$2:$S$3501,Raw_Data!$P$2:$P$3501,"IBM") -> 12.55
A33: Infosys | B33: =AVERAGEIF(Raw_Data!$P$2:$P$3501,"Infosys",Raw_Data!$S$2:$S$3501) -> 6.2783618 | C33: =_xlfn.MAXIFS(Raw_Data!$S$2:$S$3501,Raw_Data!$P$2:$P$3501,"Infosys") -> 9.49
A34: Microsoft | B34: =AVERAGEIF(Raw_Data!$P$2:$P$3501,"Microsoft",Raw_Data!$S$2:$S$3501) -> 19.55771 | C34: =_xlfn.MAXIFS(Raw_Data!$S$2:$S$3501,Raw_Data!$P$2:$P$3501,"Microsoft") -> 23.34
A35: TCS | B35: =AVERAGEIF(Raw_Data!$P$2:$P$3501,"TCS",Raw_Data!$S$2:$S$3501) -> 5.9132082 | C35: =_xlfn.MAXIFS(Raw_Data!$S$2:$S$3501,Raw_Data!$P$2:$P$3501,"TCS") -> 9.3
A36: Wipro | B36: =AVERAGEIF(Raw_Data!$P$2:$P$3501,"Wipro",Raw_Data!$S$2:$S$3501) -> 6.1509609 | C36: =_xlfn.MAXIFS(Raw_Data!$S$2:$S$3501,Raw_Data!$P$2:$P$3501,"Wipro") -> 9.69
A38: Average Package by Job Role
A39: Job_Role | B39: Average Package (LPA)
A40: Business Analyst | B40: =AVERAGEIF(Raw_Data!$R$2:$R$3501,"Business Analyst",Raw_Data!$S$2:$S$3501) -> 9.0290376
A41: Cloud Engineer | B41: =AVERAGEIF(Raw_Data!$R$2:$R$3501,"Cloud Engineer",Raw_Data!$S$2:$S$3501) -> 9.3826404
A42: Data Analyst | B42: =AVERAGEIF(Raw_Data!$R$2:$R$3501,"Data Analyst",Raw_Data!$S$2:$S$3501) -> 9.265404
A43: DevOps Engineer | B43: =AVERAGEIF(Raw_Data!$R$2:$R$3501,"DevOps Engineer",Raw_Data!$S$2:$S$3501) -> 9.1372559
A44: Full Stack Developer | B44: =AVERAGEIF(Raw_Data!$R$2:$R$3501,"Full Stack Developer",Raw_Data!$S$2:$S$3501) -> 9.4851451
A45: QA Engineer | B45: =AVERAGEIF(Raw_Data!$R$2:$R$3501,"QA Engineer",Raw_Data!$S$2:$S$3501) -> 8.8943519
A46: Software Engineer | B46: =AVERAGEIF(Raw_Data!$R$2:$R$3501,"Software Engineer",Raw_Data!$S$2:$S$3501) -> 8.8103883

Sheet Student_Analysis
A1: STUDENT PERFORMANCE ANALYSIS
A3: Performance Factors: Placed vs Unplaced (Averages)
A4: Factor | B4: Avg (Placed) | C4: Avg (Unplaced)
A5: CGPA | B5: =AVERAGEIF(Raw_Data!$O$2:$O$3501,"Placed",Raw_Data!$F$2:$F$3501) -> 7.7593381 | C5: =AVERAGEIF(Raw_Data!$O$2:$O$3501,"Unplaced",Raw_Data!$F$2:$F$3501) -> 7.2606944
A6: Attendance (%) | B6: =AVERAGEIF(Raw_Data!$O$2:$O$3501,"Placed",Raw_Data!$G$2:$G$3501) -> 82.143669 | C6: =AVERAGEIF(Raw_Data!$O$2:$O$3501,"Unplaced",Raw_Data!$G$2:$G$3501) -> 81.088194
A7: Internships | B7: =AVERAGEIF(Raw_Data!$O$2:$O$3501,"Placed",Raw_Data!$H$2:$H$3501) -> 1.3741007 | C7: =AVERAGEIF(Raw_Data!$O$2:$O$3501,"Unplaced",Raw_Data!$H$2:$H$3501) -> 1.1708333
A8: Certifications | B8: =AVERAGEIF(Raw_Data!$O$2:$O$3501,"Placed",Raw_Data!$I$2:$I$3501) -> 1.9881295 | C8: =AVERAGEIF(Raw_Data!$O$2:$O$3501,"Unplaced",Raw_Data!$I$2:$I$3501) -> 1.8222222
A9: Projects Completed | B9: =AVERAGEIF(Raw_Data!$O$2:$O$3501,"Placed",Raw_Data!$J$2:$J$3501) -> 3.7151079 | C9: =AVERAGEIF(Raw_Data!$O$2:$O$3501,"Unplaced",Raw_Data!$J$2:$J$3501) -> 3.5333333
A10: Aptitude Score | B10: =AVERAGEIF(Raw_Data!$O$2:$O$3501,"Placed",Raw_Data!$K$2:$K$3501) -> 67.730108 | C10: =AVERAGEIF(Raw_Data!$O$2:$O$3501,"Unplaced",Raw_Data!$K$2:$K$3501) -> 68.440694
A11: Technical Score | B11: =AVERAGEIF(Raw_Data!$O$2:$O$3501,"Placed",Raw_Data!$L$2:$L$3501) -> 70.351619 | C11: =AVERAGEIF(Raw_Data!$O$2:$O$3501,"Unplaced",Raw_Data!$L$2:$L$3501) -> 68.345417
A12: HR Score | B12: =AVERAGEIF(Raw_Data!$O$2:$O$3501,"Placed",Raw_Data!$M$2:$M$3501) -> 73.788453 | C12: =AVERAGEIF(Raw_Data!$O$2:$O$3501,"Unplaced",Raw_Data!$M$2:$M$3501) -> 73.375556
A13: Backlogs | B13: =AVERAGEIF(Raw_Data!$O$2:$O$3501,"Placed",Raw_Data!$N$2:$N$3501) -> 0.36798561 | C13: =AVERAGEIF(Raw_Data!$O$2:$O$3501,"Unplaced",Raw_Data!$N$2:$N$3501) -> 0.55138889
A21: Placement Rate by CGPA Band
A22: CGPA Band | B22: Total Students | C22: Placement Rate
A23: < 6.5 | B23: =COUNTIFS(Raw_Data!$F$2:$F$3501,">="&0,Raw_Data!$F$2:$F$3501,"<"&6.5) -> 358 | C23: =IFERROR(COUNTIFS(Raw_Data!$F$2:$F$3501,">="&0,Raw_Data!$F$2:$F$3501,"<"&6.5,Raw_Data!$O$2:$O$3501,"Placed")/B23,0) -> 0.62569832
A24: 6.5 - 7.5 | B24: =COUNTIFS(Raw_Data!$F$2:$F$3501,">="&6.5,Raw_Data!$F$2:$F$3501,"<"&7.5) -> 1152 | C24: =IFERROR(COUNTIFS(Raw_Data!$F$2:$F$3501,">="&6.5,Raw_Data!$F$2:$F$3501,"<"&7.5,Raw_Data!$O$2:$O$3501,"Placed")/B24,0) -> 0.734375
A25: 7.5 - 8.5 | B25: =COUNTIFS(Raw_Data!$F$2:$F$3501,">="&7.5,Raw_Data!$F$2:$F$3501,"<"&8.5) -> 1368 | C25: =IFERROR(COUNTIFS(Raw_Data!$F$2:$F$3501,">="&7.5,Raw_Data!$F$2:$F$3501,"<"&8.5,Raw_Data!$O$2:$O$3501,"Placed")/B25,0) -> 0.84137427
A26: 8.5 - 9.5 | B26: =COUNTIFS(Raw_Data!$F$2:$F$3501,">="&8.5,Raw_Data!$F$2:$F$3501,"<"&9.5) -> 544 | C26: =IFERROR(COUNTIFS(Raw_Data!$F$2:$F$3501,">="&8.5,Raw_Data!$F$2:$F$3501,"<"&9.5,Raw_Data!$O$2:$O$3501,"Placed")/B26,0) -> 0.89705882
A27: 9.5 - 10.0 | B27: =COUNTIFS(Raw_Data!$F$2:$F$3501,">="&9.5,Raw_Data!$F$2:$F$3501,"<"&10.01) -> 78 | C27: =IFERROR(COUNTIFS(Raw_Data!$F$2:$F$3501,">="&9.5,Raw_Data!$F$2:$F$3501,"<"&10.01,Raw_Data!$O$2:$O$3501,"Placed")/B27,0) -> 0.91025641
A28: Placement Rate by Attendance Band
A29: Attendance Band | B29: Total Students | C29: Placement Rate
A30: < 65% | B30: =COUNTIFS(Raw_Data!$G$2:$G$3501,">="&0,Raw_Data!$G$2:$G$3501,"<"&65) -> 97 | C30: =IFERROR(COUNTIFS(Raw_Data!$G$2:$G$3501,">="&0,Raw_Data!$G$2:$G$3501,"<"&65,Raw_Data!$O$2:$O$3501,"Placed")/B30,0) -> 0.75257732
A31: 65 - 75% | B31: =COUNTIFS(Raw_Data!$G$2:$G$3501,">="&65,Raw_Data!$G$2:$G$3501,"<"&75) -> 645 | C31: =IFERROR(COUNTIFS(Raw_Data!$G$2:$G$3501,">="&65,Raw_Data!$G$2:$G$3501,"<"&75,Raw_Data!$O$2:$O$3501,"Placed")/B31,0) -> 0.75503876
A32: 75 - 85% | B32: =COUNTIFS(Raw_Data!$G$2:$G$3501,">="&75,Raw_Data!$G$2:$G$3501,"<"&85) -> 1465 | C32: =IFERROR(COUNTIFS(Raw_Data!$G$2:$G$3501,">="&75,Raw_Data!$G$2:$G$3501,"<"&85,Raw_Data!$O$2:$O$3501,"Placed")/B32,0) -> 0.79863481
A33: 85 - 95% | B33: =COUNTIFS(Raw_Data!$G$2:$G$3501,">="&85,Raw_Data!$G$2:$G$3501,"<"&95) -> 1037 | C33: =IFERROR(COUNTIFS(Raw_Data!$G$2:$G$3501,">="&85,Raw_Data!$G$2:$G$3501,"<"&95,Raw_Data!$O$2:$O$3501,"Placed")/B33,0) -> 0.81195757
A34: 95 - 100% | B34: =COUNTIFS(Raw_Data!$G$2:$G$3501,">="&95,Raw_Data!$G$2:$G$3501,"<"&100.01) -> 256 | C34: =IFERROR(COUNTIFS(Raw_Data!$G$2:$G$3501,">="&95,Raw_Data!$G$2:$G$3501,"<"&100.01,Raw_Data!$O$2:$O$3501,"Placed")/B34,0) -> 0.8125

Sheet Top_Students
A1: TOP 10 STUDENTS
A3: Top 10 Students by CGPA
A4: Student_ID | B4: Department | C4: CGPA | D4: Technical_Score | E4: Company | F4: Job_Role | G4: Package_LPA
A5: =INDEX(Raw_Data!$A:$A,$I5) -> STU10303 | B5: =INDEX(Raw_Data!$C:$C,$I5) -> ECE | C5: =INDEX(Raw_Data!$F:$F,$I5) -> 10 | D5: =INDEX(Raw_Data!$L:$L,$I5) -> 83.8 | E5: =INDEX(Raw_Data!$P:$P,$I5) -> Microsoft | F5: =INDEX(Raw_Data!$R:$R,$I5) -> Software Engineer | G5: =INDEX(Raw_Data!$S:$S,$I5) -> 21.47 | I5: =MATCH(LARGE(Raw_Data!$X$2:$X$3501,1),Raw_Data!$X$2:$X$3501,0)+1 -> 304
A6: =INDEX(Raw_Data!$A:$A,$I6) -> STU10706 | B6: =INDEX(Raw_Data!$C:$C,$I6) -> ECE | C6: =INDEX(Raw_Data!$F:$F,$I6) -> 10 | D6: =INDEX(Raw_Data!$L:$L,$I6) -> 74.2 | E6: =INDEX(Raw_Data!$P:$P,$I6) -> IBM | F6: =INDEX(Raw_Data!$R:$R,$I6) -> DevOps Engineer | G6: =INDEX(Raw_Data!$S:$S,$I6) -> 9.21 | I6: =MATCH(LARGE(Raw_Data!$X$2:$X$3501,2),Raw_Data!$X$2:$X$3501,0)+1 -> 707
A7: =INDEX(Raw_Data!$A:$A,$I7) -> STU10826 | B7: =INDEX(Raw_Data!$C:$C,$I7) -> ECE | C7: =INDEX(Raw_Data!$F:$F,$I7) -> 10 | D7: =INDEX(Raw_Data!$L:$L,$I7) -> 81.6 | E7: =INDEX(Raw_Data!$P:$P,$I7) -> Deloitte | F7: =INDEX(Raw_Data!$R:$R,$I7) -> DevOps Engineer | G7: =INDEX(Raw_Data!$S:$S,$I7) -> 9.94 | I7: =MATCH(LARGE(Raw_Data!$X$2:$X$3501,3),Raw_Data!$X$2:$X$3501,0)+1 -> 827
A8: =INDEX(Raw_Data!$A:$A,$I8) -> STU10966 | B8: =INDEX(Raw_Data!$C:$C,$I8) -> CSE | C8: =INDEX(Raw_Data!$F:$F,$I8) -> 10 | D8: =INDEX(Raw_Data!$L:$L,$I8) -> 47.5 | E8: =INDEX(Raw_Data!$P:$P,$I8) -> Microsoft | F8: =INDEX(Raw_Data!$R:$R,$I8) -> Full Stack Developer | G8: =INDEX(Raw_Data!$S:$S,$I8) -> 20.88 | I8: =MATCH(LARGE(Raw_Data!$X$2:$X$3501,4),Raw_Data!$X$2:$X$3501,0)+1 -> 967
A9: =INDEX(Raw_Data!$A:$A,$I9) -> STU11052 | B9: =INDEX(Raw_Data!$C:$C,$I9) -> EEE | C9: =INDEX(Raw_Data!$F:$F,$I9) -> 10 | D9: =INDEX(Raw_Data!$L:$L,$I9) -> 66.4 | E9: =INDEX(Raw_Data!$P:$P,$I9) -> Amazon | F9: =INDEX(Raw_Data!$R:$R,$I9) -> DevOps Engineer | G9: =INDEX(Raw_Data!$S:$S,$I9) -> 16.88 | I9: =MATCH(LARGE(Raw_Data!$X$2:$X$3501,5),Raw_Data!$X$2:$X$3501,0)+1 -> 1053
A10: =INDEX(Raw_Data!$A:$A,$I10) -> STU11167 | B10: =INDEX(Raw_Data!$C:$C,$I10) -> ECE | C10: =INDEX(Raw_Data!$F:$F,$I10) -> 10 | D10: =INDEX(Raw_Data!$L:$L,$I10) -> 75.7 | E10: =INDEX(Raw_Data!$P:$P,$I10) -> Accenture | F10: =INDEX(Raw_Data!$R:$R,$I10) -> DevOps Engineer | G10: =INDEX(Raw_Data!$S:$S,$I10) -> 8.32 | I10: =MATCH(LARGE(Raw_Data!$X$2:$X$3501,6),Raw_Data!$X$2:$X$3501,0)+1 -> 1168
A11: =INDEX(Raw_Data!$A:$A,$I11) -> STU11290 | B11: =INDEX(Raw_Data!$C:$C,$I11) -> IT | C11: =INDEX(Raw_Data!$F:$F,$I11) -> 10 | D11: =INDEX(Raw_Data!$L:$L,$I11) -> 67.5 | E11: =INDEX(Raw_Data!$P:$P,$I11) -> Infosys | F11: =INDEX(Raw_Data!$R:$R,$I11) -> Business Analyst | G11: =INDEX(Raw_Data!$S:$S,$I11) -> 9.09 | I11: =MATCH(LARGE(Raw_Data!$X$2:$X$3501,7),Raw_Data!$X$2:$X$3501,0)+1 -> 1291
A12: =INDEX(Raw_Data!$A:$A,$I12) -> STU11707 | B12: =INDEX(Raw_Data!$C:$C,$I12) -> EEE | C12: =INDEX(Raw_Data!$F:$F,$I12) -> 10 | D12: =INDEX(Raw_Data!$L:$L,$I12) -> 59.9 | E12: =INDEX(Raw_Data!$P:$P,$I12) -> Cognizant | F12: =INDEX(Raw_Data!$R:$R,$I12) -> Software Engineer | G12: =INDEX(Raw_Data!$S:$S,$I12) -> 7.61 | I12: =MATCH(LARGE(Raw_Data!$X$2:$X$3501,8),Raw_Data!$X$2:$X$3501,0)+1 -> 1708
A13: =INDEX(Raw_Data!$A:$A,$I13) -> STU11864 | B13: =INDEX(Raw_Data!$C:$C,$I13) -> IT | C13: =INDEX(Raw_Data!$F:$F,$I13) -> 10 | D13: =INDEX(Raw_Data!$L:$L,$I13) -> 100 | E13: =INDEX(Raw_Data!$P:$P,$I13) -> IBM | F13: =INDEX(Raw_Data!$R:$R,$I13) -> Business Analyst | G13: =INDEX(Raw_Data!$S:$S,$I13) -> 12.55 | I13: =MATCH(LARGE(Raw_Data!$X$2:$X$3501,9),Raw_Data!$X$2:$X$3501,0)+1 -> 1865
A14: =INDEX(Raw_Data!$A:$A,$I14) -> STU11989 | B14: =INDEX(Raw_Data!$C:$C,$I14) -> MECH | C14: =INDEX(Raw_Data!$F:$F,$I14) -> 10 | D14: =INDEX(Raw_Data!$L:$L,$I14) -> 72.6 | E14: =INDEX(Raw_Data!$P:$P,$I14) -> TCS | F14: =INDEX(Raw_Data!$R:$R,$I14) -> Software Engineer | G14: =INDEX(Raw_Data!$S:$S,$I14) -> 6.04 | I14: =MATCH(LARGE(Raw_Data!$X$2:$X$3501,10),Raw_Data!$X$2:$X$3501,0)+1 -> 1990
A15: Top 10 Students by Package
A16: Student_ID | B16: Department | C16: CGPA | D16: Technical_Score | E16: Company | F16: Job_Role | G16: Package_LPA
A17: =INDEX(Raw_Data!$A:$A,$I17) -> STU10454 | B17: =INDEX(Raw_Data!$C:$C,$I17) -> ECE | C17: =INDEX(Raw_Data!$F:$F,$I17) -> 9.58 | D17: =INDEX(Raw_Data!$L:$L,$I17) -> 100 | E17: =INDEX(Raw_Data!$P:$P,$I17) -> Microsoft | F17: =INDEX(Raw_Data!$R:$R,$I17) -> Data Analyst | G17: =INDEX(Raw_Data!$S:$S,$I17) -> 23.34 | I17: =MATCH(LARGE(Raw_Data!$Y$2:$Y$3501,1),Raw_Data!$Y$2:$Y$3501,0)+1 -> 455
A18: =INDEX(Raw_Data!$A:$A,$I18) -> STU11364 | B18: =INDEX(Raw_Data!$C:$C,$I18) -> CIVIL | C18: =INDEX(Raw_Data!$F:$F,$I18) -> 8.25 | D18: =INDEX(Raw_Data!$L:$L,$I18) -> 94.3 | E18: =INDEX(Raw_Data!$P:$P,$I18) -> Microsoft | F18: =INDEX(Raw_Data!$R:$R,$I18) -> DevOps Engineer | G18: =INDEX(Raw_Data!$S:$S,$I18) -> 22.18 | I18: =MATCH(LARGE(Raw_Data!$Y$2:$Y$3501,2),Raw_Data!$Y$2:$Y$3501,0)+1 -> 1365
A19: =INDEX(Raw_Data!$A:$A,$I19) -> STU12833 | B19: =INDEX(Raw_Data!$C:$C,$I19) -> AIML | C19: =INDEX(Raw_Data!$F:$F,$I19) -> 9.41 | D19: =INDEX(Raw_Data!$L:$L,$I19) -> 100 | E19: =INDEX(Raw_Data!$P:$P,$I19) -> Microsoft | F19: =INDEX(Raw_Data!$R:$R,$I19) -> Software Engineer | G19: =INDEX(Raw_Data!$S:$S,$I19) -> 22.13 | I19: =MATCH(LARGE(Raw_Data!$Y$2:$Y$3501,3),Raw_Data!$Y$2:$Y$3501,0)+1 -> 2834
A20: =INDEX(Raw_Data!$A:$A,$I20) -> STU13324 | B20: =INDEX(Raw_Data!$C:$C,$I20) -> IT | C20: =INDEX(Raw_Data!$F:$F,$I20) -> 8.29 | D20: =INDEX(Raw_Data!$L:$L,$I20) -> 92 | E20: =INDEX(Raw_Data!$P:$P,$I20) -> Microsoft | F20: =INDEX(Raw_Data!$R:$R,$I20) -> Data Analyst | G20: =INDEX(Raw_Data!$S:$S,$I20) -> 21.84 | I20: =MATCH(LARGE(Raw_Data!$Y$2:$Y$3501,4),Raw_Data!$Y$2:$Y$3501,0)+1 -> 3325
A21: =INDEX(Raw_Data!$A:$A,$I21) -> STU12446 | B21: =INDEX(Raw_Data!$C:$C,$I21) -> EEE | C21: =INDEX(Raw_Data!$F:$F,$I21) -> 9.98 | D21: =INDEX(Raw_Data!$L:$L,$I21) -> 82.2 | E21: =INDEX(Raw_Data!$P:$P,$I21) -> Microsoft | F21: =INDEX(Raw_Data!$R:$R,$I21) -> DevOps Engineer | G21: =INDEX(Raw_Data!$S:$S,$I21) -> 21.75 | I21: =MATCH(LARGE(Raw_Data!$Y$2:$Y$3501,5),Raw_Data!$Y$2:$Y$3501,0)+1 -> 2447
A22: =INDEX(Raw_Data!$A:$A,$I22) -> STU12702 | B22: =INDEX(Raw_Data!$C:$C,$I22) -> IT | C22: =INDEX(Raw_Data!$F:$F,$I22) -> 9.3 | D22: =INDEX(Raw_Data!$L:$L,$I22) -> 90.9 | E22: =INDEX(Raw_Data!$P:$P,$I22) -> Microsoft | F22: =INDEX(Raw_Data!$R:$R,$I22) -> Software Engineer | G22: =INDEX(Raw_Data!$S:$S,$I22) -> 21.74 | I22: =MATCH(LARGE(Raw_Data!$Y$2:$Y$3501,6),Raw_Data!$Y$2:$Y$3501,0)+1 -> 2703
A23: =INDEX(Raw_Data!$A:$A,$I23) -> STU12924 | B23: =INDEX(Raw_Data!$C:$C,$I23) -> AIML | C23: =INDEX(Raw_Data!$F:$F,$I23) -> 7.96 | D23: =INDEX(Raw_Data!$L:$L,$I23) -> 89.7 | E23: =INDEX(Raw_Data!$P:$P,$I23) -> Microsoft | F23: =INDEX(Raw_Data!$R:$R,$I23) -> Cloud Engineer | G23: =INDEX(Raw_Data!$S:$S,$I23) -> 21.73 | I23: =MATCH(LARGE(Raw_Data!$Y$2:$Y$3501,7),Raw_Data!$Y$2:$Y$3501,0)+1 -> 2925
A24: =INDEX(Raw_Data!$A:$A,$I24) -> STU10651 | B24: =INDEX(Raw_Data!$C:$C,$I24) -> AIML | C24: =INDEX(Raw_Data!$F:$F,$I24) -> 8.97 | D24: =INDEX(Raw_Data!$L:$L,$I24) -> 87.2 | E24: =INDEX(Raw_Data!$P:$P,$I24) -> Microsoft | F24: =INDEX(Raw_Data!$R:$R,$I24) -> Full Stack Developer | G24: =INDEX(Raw_Data!$S:$S,$I24) -> 21.68 | I24: =MATCH(LARGE(Raw_Data!$Y$2:$Y$3501,8),Raw_Data!$Y$2:$Y$3501,0)+1 -> 652
A25: =INDEX(Raw_Data!$A:$A,$I25) -> STU12748 | B25: =INDEX(Raw_Data!$C:$C,$I25) -> ECE | C25: =INDEX(Raw_Data!$F:$F,$I25) -> 8.4 | D25: =INDEX(Raw_Data!$L:$L,$I25) -> 70.8 | E25: =INDEX(Raw_Data!$P:$P,$I25) -> Microsoft | F25: =INDEX(Raw_Data!$R:$R,$I25) -> QA Engineer | G25: =INDEX(Raw_Data!$S:$S,$I25) -> 21.68 | I25: =MATCH(LARGE(Raw_Data!$Y$2:$Y$3501,9),Raw_Data!$Y$2:$Y$3501,0)+1 -> 2749
A26: =INDEX(Raw_Data!$A:$A,$I26) -> STU11354 | B26: =INDEX(Raw_Data!$C:$C,$I26) -> CIVIL | C26: =INDEX(Raw_Data!$F:$F,$I26) -> 7.37 | D26: =INDEX(Raw_Data!$L:$L,$I26) -> 81.5 | E26: =INDEX(Raw_Data!$P:$P,$I26) -> Microsoft | F26: =INDEX(Raw_Data!$R:$R,$I26) -> Cloud Engineer | G26: =INDEX(Raw_Data!$S:$S,$I26) -> 21.65 | I26: =MATCH(LARGE(Raw_Data!$Y$2:$Y$3501,10),Raw_Data!$Y$2:$Y$3501,0)+1 -> 1355
A27: Top 10 Students by Technical Score
A28: Student_ID | B28: Department | C28: CGPA | D28: Technical_Score | E28: Company | F28: Job_Role | G28: Package_LPA
A29: =INDEX(Raw_Data!$A:$A,$I29) -> STU10079 | B29: =INDEX(Raw_Data!$C:$C,$I29) -> CSE | C29: =INDEX(Raw_Data!$F:$F,$I29) -> 7.3 | D29: =INDEX(Raw_Data!$L:$L,$I29) -> 100 | E29: =INDEX(Raw_Data!$P:$P,$I29) -> Cognizant | F29: =INDEX(Raw_Data!$R:$R,$I29) -> Data Analyst | G29: =INDEX(Raw_Data!$S:$S,$I29) -> 7.73 | I29: =MATCH(LARGE(Raw_Data!$Z$2:$Z$3501,1),Raw_Data!$Z$2:$Z$3501,0)+1 -> 80
A30: =INDEX(Raw_Data!$A:$A,$I30) -> STU10099 | B30: =INDEX(Raw_Data!$C:$C,$I30) -> MECH | C30: =INDEX(Raw_Data!$F:$F,$I30) -> 9.63 | D30: =INDEX(Raw_Data!$L:$L,$I30) -> 100 | E30: =INDEX(Raw_Data!$P:$P,$I30) -> Infosys | F30: =INDEX(Raw_Data!$R:$R,$I30) -> QA Engineer | G30: =INDEX(Raw_Data!$S:$S,$I30) -> 9.49 | I30: =MATCH(LARGE(Raw_Data!$Z$2:$Z$3501,2),Raw_Data!$Z$2:$Z$3501,0)+1 -> 100
A31: =INDEX(Raw_Data!$A:$A,$I31) -> STU10102 | B31: =INDEX(Raw_Data!$C:$C,$I31) -> MECH | C31: =INDEX(Raw_Data!$F:$F,$I31) -> 7.46 | D31: =INDEX(Raw_Data!$L:$L,$I31) -> 100 | E31: =INDEX(Raw_Data!$P:$P,$I31) -> Amazon | F31: =INDEX(Raw_Data!$R:$R,$I31) -> Data Analyst | G31: =INDEX(Raw_Data!$S:$S,$I31) -> 18.25 | I31: =MATCH(LARGE(Raw_Data!$Z$2:$Z$3501,3),Raw_Data!$Z$2:$Z$3501,0)+1 -> 103
A32: =INDEX(Raw_Data!$A:$A,$I32) -> STU10135 | B32: =INDEX(Raw_Data!$C:$C,$I32) -> CSE | C32: =INDEX(Raw_Data!$F:$F,$I32) -> 7.04 | D32: =INDEX(Raw_Data!$L:$L,$I32) -> 100 | E32: =INDEX(Raw_Data!$P:$P,$I32) -> Infosys | F32: =INDEX(Raw_Data!$R:$R,$I32) -> DevOps Engineer | G32: =INDEX(Raw_Data!$S:$S,$I32) -> 6.55 | I32: =MATCH(LARGE(Raw_Data!$Z$2:$Z$3501,4),Raw_Data!$Z$2:$Z$3501,0)+1 -> 136
A33: =INDEX(Raw_Data!$A:$A,$I33) -> STU10144 | B33: =INDEX(Raw_Data!$C:$C,$I33) -> MECH | C33: =INDEX(Raw_Data!$F:$F,$I33) -> 7.86 | D33: =INDEX(Raw_Data!$L:$L,$I33) -> 100 | E33: =INDEX(Raw_Data!$P:$P,$I33) -> Cognizant | F33: =INDEX(Raw_Data!$R:$R,$I33) -> Business Analyst | G33: =INDEX(Raw_Data!$S:$S,$I33) -> 7.77 | I33: =MATCH(LARGE(Raw_Data!$Z$2:$Z$3501,5),Raw_Data!$Z$2:$Z$3501,0)+1 -> 145
A34: =INDEX(Raw_Data!$A:$A,$I34) -> STU10149 | B34: =INDEX(Raw_Data!$C:$C,$I34) -> AIML | C34: =INDEX(Raw_Data!$F:$F,$I34) -> 7.6 | D34: =INDEX(Raw_Data!$L:$L,$I34) -> 100 | E34: =INDEX(Raw_Data!$P:$P,$I34) -> Not Placed | F34: =INDEX(Raw_Data!$R:$R,$I34) -> 0 | G34: =INDEX(Raw_Data!$S:$S,$I34) -> 0 | I34: =MATCH(LARGE(Raw_Data!$Z$2:$Z$3501,6),Raw_Data!$Z$2:$Z$3501,0)+1 -> 150
A35: =INDEX(Raw_Data!$A:$A,$I35) -> STU10200 | B35: =INDEX(Raw_Data!$C:$C,$I35) -> CSE | C35: =INDEX(Raw_Data!$F:$F,$I35) -> 8.47 | D35: =INDEX(Raw_Data!$L:$L,$I35) -> 100 | E35: =INDEX(Raw_Data!$P:$P,$I35) -> TCS | F35: =INDEX(Raw_Data!$R:$R,$I35) -> QA Engineer | G35: =INDEX(Raw_Data!$S:$S,$I35) -> 7.66 | I35: =MATCH(LARGE(Raw_Data!$Z$2:$Z$3501,7),Raw_Data!$Z$2:$Z$3501,0)+1 -> 201
A36: =INDEX(Raw_Data!$A:$A,$I36) -> STU10222 | B36: =INDEX(Raw_Data!$C:$C,$I36) -> MECH | C36: =INDEX(Raw_Data!$F:$F,$I36) -> 9.06 | D36: =INDEX(Raw_Data!$L:$L,$I36) -> 100 | E36: =INDEX(Raw_Data!$P:$P,$I36) -> Capgemini | F36: =INDEX(Raw_Data!$R:$R,$I36) -> DevOps Engineer | G36: =INDEX(Raw_Data!$S:$S,$I36) -> 10.04 | I36: =MATCH(LARGE(Raw_Data!$Z$2:$Z$3501,8),Raw_Data!$Z$2:$Z$3501,0)+1 -> 223
A37: =INDEX(Raw_Data!$A:$A,$I37) -> STU10236 | B37: =INDEX(Raw_Data!$C:$C,$I37) -> EEE | C37: =INDEX(Raw_Data!$F:$F,$I37) -> 6.92 | D37: =INDEX(Raw_Data!$L:$L,$I37) -> 100 | E37: =INDEX(Raw_Data!$P:$P,$I37) -> Wipro | F37: =INDEX(Raw_Data!$R:$R,$I37) -> Cloud Engineer | G37: =INDEX(Raw_Data!$S:$S,$I37) -> 7.62 | I37: =MATCH(LARGE(Raw_Data!$Z$2:$Z$3501,9),Raw_Data!$Z$2:$Z$3501,0)+1 -> 237
A38: =INDEX(Raw_Data!$A:$A,$I38) -> STU10237 | B38: =INDEX(Raw_Data!$C:$C,$I38) -> IT | C38: =INDEX(Raw_Data!$F:$F,$I38) -> 9.22 | D38: =INDEX(Raw_Data!$L:$L,$I38) -> 100 | E38: =INDEX(Raw_Data!$P:$P,$I38) -> Wipro | F38: =INDEX(Raw_Data!$R:$R,$I38) -> Full Stack Developer | G38: =INDEX(Raw_Data!$S:$S,$I38) -> 8.75 | I38: =MATCH(LARGE(Raw_Data!$Z$2:$Z$3501,10),Raw_Data!$Z$2:$Z$3501,0)+1 -> 238

Sheet Recruiter_Analysis
A1: RECRUITER ANALYSIS
A3: Company | B3: Hiring Count | C3: Average Package (LPA) | D3: Highest Package (LPA) | E3: Industry | F3: Distinct Job Roles Offered
A4: Accenture | B4: =COUNTIF(Raw_Data!$P$2:$P$3501,"Accenture") -> 298 | C4: =AVERAGEIF(Raw_Data!$P$2:$P$3501,"Accenture",Raw_Data!$S$2:$S$3501) -> 7.0176846 | D4: =_xlfn.MAXIFS(Raw_Data!$S$2:$S$3501,Raw_Data!$P$2:$P$3501,"Accenture") -> 9.96 | E4: =INDEX(Raw_Data!$Q$2:$Q$3501,MATCH("Accenture",Raw_Data!$P$2:$P$3501,0)) -> Consulting | F4: =SUMPRODUCT((COUNTIFS(Raw_Data!$P$2:$P$3501,"Accenture",Raw_Data!$R$2:$R$3501,{"Business Analyst","Cloud Engineer","Data Analyst","DevOps Engineer","Full Stack Developer","QA Engineer","Software Engineer"})>0)*1) -> 7
A5: Microsoft | B5: =COUNTIF(Raw_Data!$P$2:$P$3501,"Microsoft") -> 297 | C5: =AVERAGEIF(Raw_Data!$P$2:$P$3501,"Microsoft",Raw_Data!$S$2:$S$3501) -> 19.55771 | D5: =_xlfn.MAXIFS(Raw_Data!$S$2:$S$3501,Raw_Data!$P$2:$P$3501,"Microsoft") -> 23.34 | E5: =INDEX(Raw_Data!$Q$2:$Q$3501,MATCH("Microsoft",Raw_Data!$P$2:$P$3501,0)) -> Software Product | F5: =SUMPRODUCT((COUNTIFS(Raw_Data!$P$2:$P$3501,"Microsoft",Raw_Data!$R$2:$R$3501,{"Business Analyst","Cloud Engineer","Data Analyst","DevOps Engineer","Full Stack Developer","QA Engineer","Software Engineer"})>0)*1) -> 7
A6: TCS | B6: =COUNTIF(Raw_Data!$P$2:$P$3501,"TCS") -> 293 | C6: =AVERAGEIF(Raw_Data!$P$2:$P$3501,"TCS",Raw_Data!$S$2:$S$3501) -> 5.9132082 | D6: =_xlfn.MAXIFS(Raw_Data!$S$2:$S$3501,Raw_Data!$P$2:$P$3501,"TCS") -> 9.3 | E6: =INDEX(Raw_Data!$Q$2:$Q$3501,MATCH("TCS",Raw_Data!$P$2:$P$3501,0)) -> IT Services | F6: =SUMPRODUCT((COUNTIFS(Raw_Data!$P$2:$P$3501,"TCS",Raw_Data!$R$2:$R$3501,{"Business Analyst","Cloud Engineer","Data Analyst","DevOps Engineer","Full Stack Developer","QA Engineer","Software Engineer"})>0)*1) -> 7
A7: Infosys | B7: =COUNTIF(Raw_Data!$P$2:$P$3501,"Infosys") -> 293 | C7: =AVERAGEIF(Raw_Data!$P$2:$P$3501,"Infosys",Raw_Data!$S$2:$S$3501) -> 6.2783618 | D7: =_xlfn.MAXIFS(Raw_Data!$S$2:$S$3501,Raw_Data!$P$2:$P$3501,"Infosys") -> 9.49 | E7: =INDEX(Raw_Data!$Q$2:$Q$3501,MATCH("Infosys",Raw_Data!$P$2:$P$3501,0)) -> IT Services | F7: =SUMPRODUCT((COUNTIFS(Raw_Data!$P$2:$P$3501,"Infosys",Raw_Data!$R$2:$R$3501,{"Business Analyst","Cloud Engineer","Data Analyst","DevOps Engineer","Full Stack Developer","QA Engineer","Software Engineer"})>0)*1) -> 7
A8: Wipro | B8: =COUNTIF(Raw_Data!$P$2:$P$3501,"Wipro") -> 281 | C8: =AVERAGEIF(Raw_Data!$P$2:$P$3501,"Wipro",Raw_Data!$S$2:$S$3501) -> 6.1509609 | D8: =_xlfn.MAXIFS(Raw_Data!$S$2:$S$3501,Raw_Data!$P$2:$P$3501,"Wipro") -> 9.69 | E8: =INDEX(Raw_Data!$Q$2:$Q$3501,MATCH("Wipro",Raw_Data!$P$2:$P$3501,0)) -> IT Services | F8: =SUMPRODUCT((COUNTIFS(Raw_Data!$P$2:$P$3501,"Wipro",Raw_Data!$R$2:$R$3501,{"Business Analyst","Cloud Engineer","Data Analyst","DevOps Engineer","Full Stack Developer","QA Engineer","Software Engineer"})>0)*1) -> 7
A9: Cognizant | B9: =COUNTIF(Raw_Data!$P$2:$P$3501,"Cognizant") -> 270 | C9: =AVERAGEIF(Raw_Data!$P$2:$P$3501,"Cognizant",Raw_Data!$S$2:$S$3501) -> 6.4715185 | D9: =_xlfn.MAXIFS(Raw_Data!$S$2:$S$3501,Raw_Data!$P$2:$P$3501,"Cognizant") -> 9.46 | E9: =INDEX(Raw_Data!$Q$2:$Q$3501,MATCH("Cognizant",Raw_Data!$P$2:$P$3501,0)) -> IT Services | F9: =SUMPRODUCT((COUNTIFS(Raw_Data!$P$2:$P$3501,"Cognizant",Raw_Data!$R$2:$R$3501,{"Business Analyst","Cloud Engineer","Data Analyst","DevOps Engineer","Full Stack Developer","QA Engineer","Software Engineer"})>0)*1) -> 7
A10: IBM | B10: =COUNTIF(Raw_Data!$P$2:$P$3501,"IBM") -> 270 | C10: =AVERAGEIF(Raw_Data!$P$2:$P$3501,"IBM",Raw_Data!$S$2:$S$3501) -> 8.4452963 | D10: =_xlfn.MAXIFS(Raw_Data!$S$2:$S$3501,Raw_Data!$P$2:$P$3501,"IBM") -> 12.55 | E10: =INDEX(Raw_Data!$Q$2:$Q$3501,MATCH("IBM",Raw_Data!$P$2:$P$3501,0)) -> Software Product | F10: =SUMPRODUCT((COUNTIFS(Raw_Data!$P$2:$P$3501,"IBM",Raw_Data!$R$2:$R$3501,{"Business Analyst","Cloud Engineer","Data Analyst","DevOps Engineer","Full Stack Developer","QA Engineer","Software Engineer"})>0)*1) -> 7
A11: Amazon | B11: =COUNTIF(Raw_Data!$P$2:$P$3501,"Amazon") -> 265 | C11: =AVERAGEIF(Raw_Data!$P$2:$P$3501,"Amazon",Raw_Data!$S$2:$S$3501) -> 15.484981 | D11: =_xlfn.MAXIFS(Raw_Data!$S$2:$S$3501,Raw_Data!$P$2:$P$3501,"Amazon") -> 18.9 | E11: =INDEX(Raw_Data!$Q$2:$Q$3501,MATCH("Amazon",Raw_Data!$P$2:$P$3501,0)) -> E-commerce | F11: =SUMPRODUCT((COUNTIFS(Raw_Data!$P$2:$P$3501,"Amazon",Raw_Data!$R$2:$R$3501,{"Business Analyst","Cloud Engineer","Data Analyst","DevOps Engineer","Full Stack Developer","QA Engineer","Software Engineer"})>0)*1) -> 7
A12: Capgemini | B12: =COUNTIF(Raw_Data!$P$2:$P$3501,"Capgemini") -> 264 | C12: =AVERAGEIF(Raw_Data!$P$2:$P$3501,"Capgemini",Raw_Data!$S$2:$S$3501) -> 6.8153788 | D12: =_xlfn.MAXIFS(Raw_Data!$S$2:$S$3501,Raw_Data!$P$2:$P$3501,"Capgemini") -> 10.25 | E12: =INDEX(Raw_Data!$Q$2:$Q$3501,MATCH("Capgemini",Raw_Data!$P$2:$P$3501,0)) -> Consulting | F12: =SUMPRODUCT((COUNTIFS(Raw_Data!$P$2:$P$3501,"Capgemini",Raw_Data!$R$2:$R$3501,{"Business Analyst","Cloud Engineer","Data Analyst","DevOps Engineer","Full Stack Developer","QA Engineer","Software Engineer"})>0)*1) -> 7
A13: Deloitte | B13: =COUNTIF(Raw_Data!$P$2:$P$3501,"Deloitte") -> 249 | C13: =AVERAGEIF(Raw_Data!$P$2:$P$3501,"Deloitte",Raw_Data!$S$2:$S$3501) -> 9.0563855 | D13: =_xlfn.MAXIFS(Raw_Data!$S$2:$S$3501,Raw_Data!$P$2:$P$3501,"Deloitte") -> 11.76 | E13: =INDEX(Raw_Data!$Q$2:$Q$3501,MATCH("Deloitte",Raw_Data!$P$2:$P$3501,0)) -> Consulting | F13: =SUMPRODUCT((COUNTIFS(Raw_Data!$P$2:$P$3501,"Deloitte",Raw_Data!$R$2:$R$3501,{"Business Analyst","Cloud Engineer","Data Analyst","DevOps Engineer","Full Stack Developer","QA Engineer","Software Engineer"})>0)*1) -> 7
